Workbook

Sheet README
A1: Modelo de agencia pericial - guía rápida
A3: Objetivo | B3: Modelar una agencia de informes periciales con captación, venta, peritación, IA y entrega.
A4: Cómo usar | B4: Edita solo las celdas amarillas/azules en ASSUMPTIONS, CHANNELS y CASE_TYPES.
A5: Qué mirar primero | B5: 1) EBITDA en PNL_24M 2) Caja en CASHFLOW_24M 3) Utilización en CAPACITY_24M 4) Sensibilidad.
A6: Fundador sin nómina | B6: Si tú haces una función, deja el FTE > 0 para mantener capacidad y pon salario = 0.
A7: Lógica | B7: Las ventas se limitan por capacidad del closer. La entrega se limita por capacidad de peritos. El exceso pasa a backlog.
A8: Horizonte | B8: 24 meses.

Sheet ASSUMPTIONS
A1: Supuestos globales
A3: Categoría | B3: Variable | C3: Valor | D3: Unidad | E3: Notas
A4: Ventas | B4: Eligible lead rate | C4: 0.7 | D4: % | E4: Porcentaje de leads realmente aptos / con potencial
A5: Ventas | B5: Contact rate | C5: 0.92 | D5: % | E5: Porcentaje de leads elegibles a los que se logra contactar
A6: Ventas | B6: Call show rate | C6: 0.78 | D6: % | E6: Porcentaje de contactados que efectivamente hablan
A7: Ventas | B7: Call close rate | C7: 0.42 | D7: % | E7: Porcentaje de llamadas que cierran en la llamada
A8: Ventas | B8: Bot recovery rate | C8: 0.22 | D8: % | E8: Porcentaje de no cerrados en llamada que acaban cerrando por WhatsApp/bot
A9: Ventas | B9: Cancellation rate | C9: 0.05 | D9: % | E9: Ventas canceladas o caídas antes de ejecutarse
A10: Cobro | B10: Current-month collection | C10: 0.9 | D10: % | E10: Cobro en el mismo mes de la venta
A11: Cobro | B11: Next-month collection | C11: 0.1 | D11: % | E11: Cobro diferido al mes siguiente
A12: Cobro | B12: Bad debt rate | C12: 0.01 | D12: % | E12: Impago / contracargo
A13: Cobro | B13: Payment processor fee | C13: 0.015 | D13: % | E13: Coste de TPV, Stripe, etc.
A14: Equipo | B14: Closer FTE | C14: 1 | D14: FTE | E14: Si el fundador hace de closer, deja FTE=1 y salario=0
A15: Equipo | B15: Closer salary / month | C15: 0 | D15: € / mes | E15: Coste fijo del closer
... A39: Modelo | B39: Starting cash | C39: 10000 | D39: € | E39: Caja inicial

Sheet CHANNELS
A1: Canales de captación
A3: Canal | B3: Driver | C3: Mes 1 | D3: Crec. mensual | E3: Coste/Parámetro | F3: Notas
A4: Paid Social | B4: Ad spend | C4: 6000 | D4: 0 | E4: 16 | F4: Parámetro = CPL
A5: Lawyer referrals | B5: Leads | C5: 15 | D5: 0.02 | E5: 0 | F5: Parámetro = coste por lead / fee equivalente
A6: Organic / direct | B6: Leads | C6: 20 | D6: 0.01 | E6: 0 | F6: Parámetro = coste por lead
A7: Other partnerships | B7: Leads | C7: 5 | D7: 0.02 | E7: 0 | F7: Parámetro = coste por lead
A9: Nota | B9: Paid Social usa Mes 1 como inversión en ads y Coste/Parámetro como CPL. El resto usan Mes 1 como leads y Coste/Parámetro como coste por lead.

Sheet CASE_TYPES
A1: Tipologías de caso
A3: Tipo | B3: Mix % | C3: PVP | D3: Desc. call | E3: Desc. bot | F3: On-site h | G3: Travel h | H3: Post h | I3: KM / caso | J3: IA var €/caso | K3: Otros var €/caso
A4: Simple | B4: 0.3 | C4: 290 | D4: 0 | E4: 0.08 | F4: 1 | G4: 0.8 | H4: 0.7 | I4: 35 | J4: 6 | K4: 8
A5: Standard | B5: 0.5 | C5: 390 | D5: 0.03 | E5: 0.1 | F5: 1.3 | G5: 1 | H5: 1 | I5: 50 | J5: 8 | K5: 12
A6: Complex | B6: 0.2 | C6: 590 | D6: 0.05 | E6: 0.12 | F6: 1.8 | G6: 1.4 | H6: 1.4 | I6: 75 | J6: 12 | K6: 18
A8: Total mix | B8: =SUM(B4:B6) -> 1
A10: Weighted listed price | B10: =SUMPRODUCT(B4:B6,C4:C6) -> 400
A11: Weighted net price - call | B11: =SUMPRODUCT(B4:B6,C4:C6*(1-D4:D6)) -> 388.25
A12: Weighted net price - bot | B12: =SUMPRODUCT(B4:B6,C4:C6*(1-E4:E6)) -> 359.38
A13: Weighted hours/case before rework | B13: =SUMPRODUCT(B4:B6,F4:F6+G4:G6+H4:H6) -> 3.32
A14: Weighted km/case | B14: =SUMPRODUCT(B4:B6,I4:I6) -> 50.5
A15: Weighted AI var/case | B15: =SUMPRODUCT(B4:B6,J4:J6) -> 8.2
A16: Weighted other var/case | B16: =SUMPRODUCT(B4:B6,K4:K6) -> 12

Sheet CAPACITY_24M
A1: Capacidad mensual
A3: Métrica | B3: M1 | C3: M2 | D3: M3 | E3: M4 | F3: M5 | G3: M6 | H3: M7 | I3: M8 | J3: M9 | K3: M10 | L3: M11 | M3: M12 | N3: M13 | O3: M14 | P3: M15 | Q3: M16 | R3: M17 | S3: M18 | T3: M19 | U3: M20 | V3: M21 | W3: M22 | X3: M23 | Y3: M24
A4: Closer available hours | B4: =ASSUMPTIONS!$C$14*ASSUMPTIONS!$C$17*ASSUMPTIONS!$C$18 -> 126 | C4: =ASSUMPTIONS!$C$14*ASSUMPTIONS!$C$17*ASSUMPTIONS!$C$18 -> 126 | D4: =ASSUMPTIONS!$C$14*ASSUMPTIONS!$C$17*ASSUMPTIONS!$C$18 -> 126 | E4: =ASSUMPTIONS!$C$14*ASSUMPTIONS!$C$17*ASSUMPTIONS!$C$18 -> 126 | F4: =ASSUMPTIONS!$C$14*ASSUMPTIONS!$C$17*ASSUMPTIONS!$C$18 -> 126 | G4: =ASSUMPTIONS!$C$14*ASSUMPTIONS!$C$17*ASSUMPTIONS!$C$18 -> 126 | H4: =ASSUMPTIONS!$C$14*ASSUMPTIONS!$C$17*ASSUMPTIONS!$C$18 -> 126 | I4: =ASSUMPTIONS!$C$14*ASSUMPTIONS!$C$17*ASSUMPTIONS!$C$18 -> 126 | ... Y4: =ASSUMPTIONS!$C$14*ASSUMPTIONS!$C$17*ASSUMPTIONS!$C$18 -> 126
A5: Avg minutes per handled call | B5: =ASSUMPTIONS!$C$19+ASSUMPTIONS!$C$20+ASSUMPTIONS!$C$21*(1-ASSUMPTIONS!$C$7) -> 33.16 | C5: =ASSUMPTIONS!$C$19+ASSUMPTIONS!$C$20+ASSUMPTIONS!$C$21*(1-ASSUMPTIONS!$C$7) -> 33.16 | D5: =ASSUMPTIONS!$C$19+ASSUMPTIONS!$C$20+ASSUMPTIONS!$C$21*(1-ASSUMPTIONS!$C$7) -> 33.16 | E5: =ASSUMPTIONS!$C$19+ASSUMPTIONS!$C$20+ASSUMPTIONS!$C$21*(1-ASSUMPTIONS!$C$7) -> 33.16 | F5: =ASSUMPTIONS!$C$19+ASSUMPTIONS!$C$20+ASSUMPTIONS!$C$21*(1-ASSUMPTIONS!$C$7) -> 33.16 | G5: =ASSUMPTIONS!$C$19+ASSUMPTIONS!$C$20+ASSUMPTIONS!$C$21*(1-ASSUMPTIONS!$C$7) -> 33.16 | H5: =ASSUMPTIONS!$C$19+ASSUMPTIONS!$C$20+ASSUMPTIONS!$C$21*(1-ASSUMPTIONS!$C$7) -> 33.16 | I5: =ASSUMPTIONS!$C$19+ASSUMPTIONS!$C$20+ASSUMPTIONS!$C$21*(1-ASSUMPTIONS!$C$7) -> 33.16 | ... Y5: =ASSUMPTIONS!$C$19+ASSUMPTIONS!$C$20+ASSUMPTIONS!$C$21*(1-ASSUMPTIONS!$C$7) -> 33.16
A6: Call capacity (calls held) | B6: =IF(B5=0,0,B4*60/B5) -> 227.98552 | C6: =IF(C5=0,0,C4*60/C5) -> 227.98552 | D6: =IF(D5=0,0,D4*60/D5) -> 227.98552 | E6: =IF(E5=0,0,E4*60/E5) -> 227.98552 | F6: =IF(F5=0,0,F4*60/F5) -> 227.98552 | G6: =IF(G5=0,0,G4*60/G5) -> 227.98552 | H6: =IF(H5=0,0,H4*60/H5) -> 227.98552 | I6: =IF(I5=0,0,I4*60/I5) -> 227.98552 | ... Y6: =IF(Y5=0,0,Y4*60/Y5) -> 227.98552
A7: Potential calls held | B7: =FUNNEL_24M!B12 -> 208.4628 | C7: =FUNNEL_24M!C12 -> 208.76419 | D7: =FUNNEL_24M!D12 -> 209.07061 | E7: =FUNNEL_24M!E12 -> 209.38214 | F7: =FUNNEL_24M!F12 -> 209.69887 | G7: =FUNNEL_24M!G12 -> 210.0209 | H7: =FUNNEL_24M!H12 -> 210.34833 | I7: =FUNNEL_24M!I12 -> 210.68126 | ... Y7: =FUNNEL_24M!Y12 -> 216.84212
A8: Call utilization | B8: =IF(B6=0,0,B7/B6) -> 0.91436858 | C8: =IF(C6=0,0,C7/C6) -> 0.91569056 | D8: =IF(D6=0,0,D7/D6) -> 0.91703457 | E8: =IF(E6=0,0,E7/E6) -> 0.91840101 | F8: =IF(F6=0,0,F7/F6) -> 0.91979028 | G8: =IF(G6=0,0,G7/G6) -> 0.9212028 | H8: =IF(H6=0,0,H7/H6) -> 0.92263899 | I8: =IF(I6=0,0,I7/I6) -> 0.92409927 | ... Y8: =IF(Y6=0,0,Y7/Y6) -> 0.95112233
A10: Perito available hours | B10: =ASSUMPTIONS!$C$22*ASSUMPTIONS!$C$26*ASSUMPTIONS!$C$27 -> 136.5 | C10: =ASSUMPTIONS!$C$22*ASSUMPTIONS!$C$26*ASSUMPTIONS!$C$27 -> 136.5 | D10: =ASSUMPTIONS!$C$22*ASSUMPTIONS!$C$26*ASSUMPTIONS!$C$27 -> 136.5 | E10: =ASSUMPTIONS!$C$22*ASSUMPTIONS!$C$26*ASSUMPTIONS!$C$27 -> 136.5 | F10: =ASSUMPTIONS!$C$22*ASSUMPTIONS!$C$26*ASSUMPTIONS!$C$27 -> 136.5 | G10: =ASSUMPTIONS!$C$22*ASSUMPTIONS!$C$26*ASSUMPTIONS!$C$27 -> 136.5 | H10: =ASSUMPTIONS!$C$22*ASSUMPTIONS!$C$26*ASSUMPTIONS!$C$27 -> 136.5 | I10: =ASSUMPTIONS!$C$22*ASSUMPTIONS!$C$26*ASSUMPTIONS!$C$27 -> 136.5 | ... Y10: =ASSUMPTIONS!$C$22*ASSUMPTIONS!$C$26*ASSUMPTIONS!$C$27 -> 136.5
A11: Weighted hours per delivered case | B11: =CASE_TYPES!$B$13+ASSUMPTIONS!$C$28*ASSUMPTIONS!$C$29 -> 3.384 | C11: =CASE_TYPES!$B$13+ASSUMPTIONS!$C$28*ASSUMPTIONS!$C$29 -> 3.384 | D11: =CASE_TYPES!$B$13+ASSUMPTIONS!$C$28*ASSUMPTIONS!$C$29 -> 3.384 | E11: =CASE_TYPES!$B$13+ASSUMPTIONS!$C$28*ASSUMPTIONS!$C$29 -> 3.384 | F11: =CASE_TYPES!$B$13+ASSUMPTIONS!$C$28*ASSUMPTIONS!$C$29 -> 3.384 | G11: =CASE_TYPES!$B$13+ASSUMPTIONS!$C$28*ASSUMPTIONS!$C$29 -> 3.384 | H11: =CASE_TYPES!$B$13+ASSUMPTIONS!$C$28*ASSUMPTIONS!$C$29 -> 3.384 | I11: =CASE_TYPES!$B$13+ASSUMPTIONS!$C$28*ASSUMPTIONS!$C$29 -> 3.384 | ... Y11: =CASE_TYPES!$B$13+ASSUMPTIONS!$C$28*ASSUMPTIONS!$C$29 -> 3.384
A12: Perito capacity (delivered cases) | B12: =IF(B11=0,0,B10/B11) -> 40.336879 | C12: =IF(C11=0,0,C10/C11) -> 40.336879 | D12: =IF(D11=0,0,D10/D11) -> 40.336879 | E12: =IF(E11=0,0,E10/E11) -> 40.336879 | F12: =IF(F11=0,0,F10/F11) -> 40.336879 | G12: =IF(G11=0,0,G10/G11) -> 40.336879 | H12: =IF(H11=0,0,H10/H11) -> 40.336879 | I12: =IF(I11=0,0,I10/I11) -> 40.336879 | ... Y12: =IF(Y11=0,0,Y10/Y11) -> 40.336879
A13: Delivered cases | B13: =PNL_24M!B8 -> 40.336879 | C13: =PNL_24M!C8 -> 40.336879 | D13: =PNL_24M!D8 -> 40.336879 | E13: =PNL_24M!E8 -> 40.336879 | F13: =PNL_24M!F8 -> 40.336879 | G13: =PNL_24M!G8 -> 40.336879 | H13: =PNL_24M!H8 -> 40.336879 | I13: =PNL_24M!I8 -> 40.336879 | ... Y13: =PNL_24M!Y8 -> 40.336879
A14: Perito utilization | B14: =IF(B12=0,0,B13/B12) -> 1 | C14: =IF(C12=0,0,C13/C12) -> 1 | D14: =IF(D12=0,0,D13/D12) -> 1 | E14: =IF(E12=0,0,E13/E12) -> 1 | F14: =IF(F12=0,0,F13/F12) -> 1 | G14: =IF(G12=0,0,G13/G12) -> 1 | H14: =IF(H12=0,0,H13/H12) -> 1 | I14: =IF(I12=0,0,I13/I12) -> 1 | ... Y14: =IF(Y12=0,0,Y13/Y12) -> 1

Sheet FUNNEL_24M
A1: Embudo mensual
A3: Métrica | B3: M1 | C3: M2 | D3: M3 | E3: M4 | F3: M5 | G3: M6 | H3: M7 | I3: M8 | J3: M9 | K3: M10 | L3: M11 | M3: M12 | N3: M13 | O3: M14 | P3: M15 | Q3: M16 | R3: M17 | S3: M18 | T3: M19 | U3: M20 | V3: M21 | W3: M22 | X3: M23 | Y3: M24
A4: Paid social ad spend | B4: =CHANNELS!$C$4 -> 6000 | C4: =B4*(1+CHANNELS!$D$4) -> 6000 | D4: =C4*(1+CHANNELS!$D$4) -> 6000 | E4: =D4*(1+CHANNELS!$D$4) -> 6000 | F4: =E4*(1+CHANNELS!$D$4) -> 6000 | G4: =F4*(1+CHANNELS!$D$4) -> 6000 | H4: =G4*(1+CHANNELS!$D$4) -> 6000 | I4: =H4*(1+CHANNELS!$D$4) -> 6000 | J4: =I4*(1+CHANNELS!$D$4) -> 6000 | ... Y4: =X4*(1+CHANNELS!$D$4) -> 6000
A5: Paid social leads | B5: =IF(CHANNELS!$E$4=0,0,B4/CHANNELS!$E$4) -> 375 | C5: =IF(CHANNELS!$E$4=0,0,C4/CHANNELS!$E$4) -> 375 | D5: =IF(CHANNELS!$E$4=0,0,D4/CHANNELS!$E$4) -> 375 | E5: =IF(CHANNELS!$E$4=0,0,E4/CHANNELS!$E$4) -> 375 | F5: =IF(CHANNELS!$E$4=0,0,F4/CHANNELS!$E$4) -> 375 | G5: =IF(CHANNELS!$E$4=0,0,G4/CHANNELS!$E$4) -> 375 | H5: =IF(CHANNELS!$E$4=0,0,H4/CHANNELS!$E$4) -> 375 | I5: =IF(CHANNELS!$E$4=0,0,I4/CHANNELS!$E$4) -> 375 | ... Y5: =IF(CHANNELS!$E$4=0,0,Y4/CHANNELS!$E$4) -> 375
A6: Lawyer referral leads | B6: =CHANNELS!$C$5 -> 15 | C6: =B6*(1+CHANNELS!$D$5) -> 15.3 | D6: =C6*(1+CHANNELS!$D$5) -> 15.606 | E6: =D6*(1+CHANNELS!$D$5) -> 15.91812 | F6: =E6*(1+CHANNELS!$D$5) -> 16.236482 | G6: =F6*(1+CHANNELS!$D$5) -> 16.561212 | H6: =G6*(1+CHANNELS!$D$5) -> 16.892436 | I6: =H6*(1+CHANNELS!$D$5) -> 17.230285 | J6: =I6*(1+CHANNELS!$D$5) -> 17.574891 | ... Y6: =X6*(1+CHANNELS!$D$5) -> 23.653489
A7: Organic/direct leads | B7: =CHANNELS!$C$6 -> 20 | C7: =B7*(1+CHANNELS!$D$6) -> 20.2 | D7: =C7*(1+CHANNELS!$D$6) -> 20.402 | E7: =D7*(1+CHANNELS!$D$6) -> 20.60602 | F7: =E7*(1+CHANNELS!$D$6) -> 20.81208 | G7: =F7*(1+CHANNELS!$D$6) -> 21.020201 | H7: =G7*(1+CHANNELS!$D$6) -> 21.230403 | I7: =H7*(1+CHANNELS!$D$6) -> 21.442707 | J7: =I7*(1+CHANNELS!$D$6) -> 21.657134 | ... Y7: =X7*(1+CHANNELS!$D$6) -> 25.14326
A8: Other partnership leads | B8: =CHANNELS!$C$7 -> 5 | C8: =B8*(1+CHANNELS!$D$7) -> 5.1 | D8: =C8*(1+CHANNELS!$D$7) -> 5.202 | E8: =D8*(1+CHANNELS!$D$7) -> 5.30604 | F8: =E8*(1+CHANNELS!$D$7) -> 5.4121608 | G8: =F8*(1+CHANNELS!$D$7) -> 5.520404 | H8: =G8*(1+CHANNELS!$D$7) -> 5.6308121 | I8: =H8*(1+CHANNELS!$D$7) -> 5.7434283 | J8: =I8*(1+CHANNELS!$D$7) -> 5.8582969 | ... Y8: =X8*(1+CHANNELS!$D$7) -> 7.8844963
A9: Total leads | B9: =SUM(B5:B8) -> 415 | C9: =SUM(C5:C8) -> 415.6 | D9: =SUM(D5:D8) -> 416.21 | E9: =SUM(E5:E8) -> 416.83018 | F9: =SUM(F5:F8) -> 417.46072 | G9: =SUM(G5:G8) -> 418.10182 | H9: =SUM(H5:H8) -> 418.75365 | I9: =SUM(I5:I8) -> 419.41642 | ... Y9: =SUM(Y5:Y8) -> 431.68125
A10: Eligible leads | B10: =B9*ASSUMPTIONS!$C$4 -> 290.5 | C10: =C9*ASSUMPTIONS!$C$4 -> 290.92 | D10: =D9*ASSUMPTIONS!$C$4 -> 291.347 | E10: =E9*ASSUMPTIONS!$C$4 -> 291.78113 | F10: =F9*ASSUMPTIONS!$C$4 -> 292.22251 | G10: =G9*ASSUMPTIONS!$C$4 -> 292.67127 | H10: =H9*ASSUMPTIONS!$C$4 -> 293.12756 | I10: =I9*ASSUMPTIONS!$C$4 -> 293.59149 | ... Y10: =Y9*ASSUMPTIONS!$C$4 -> 302.17687
A11: Contacted leads | B11: =B10*ASSUMPTIONS!$C$5 -> 267.26 | C11: =C10*ASSUMPTIONS!$C$5 -> 267.6464 | D11: =D10*ASSUMPTIONS!$C$5 -> 268.03924 | E11: =E10*ASSUMPTIONS!$C$5 -> 268.43864 | F11: =F10*ASSUMPTIONS!$C$5 -> 268.84471 | G11: =G10*ASSUMPTIONS!$C$5 -> 269.25757 | H11: =H10*ASSUMPTIONS!$C$5 -> 269.67735 | I11: =I10*ASSUMPTIONS!$C$5 -> 270.10417 | ... Y11: =Y10*ASSUMPTIONS!$C$5 -> 278.00272
A12: Potential calls held | B12: =B11*ASSUMPTIONS!$C$6 -> 208.4628 | C12: =C11*ASSUMPTIONS!$C$6 -> 208.76419 | D12: =D11*ASSUMPTIONS!$C$6 -> 209.07061 | E12: =E11*ASSUMPTIONS!$C$6 -> 209.38214 | F12: =F11*ASSUMPTIONS!$C$6 -> 209.69887 | G12: =G11*ASSUMPTIONS!$C$6 -> 210.0209 | H12: =H11*ASSUMPTIONS!$C$6 -> 210.34833 | I12: =I11*ASSUMPTIONS!$C$6 -> 210.68126 | ... Y12: =Y11*ASSUMPTIONS!$C$6 -> 216.84212
A13: Actual calls held | B13: =MIN(B12,CAPACITY_24M!B6) -> 208.4628 | C13: =MIN(C12,CAPACITY_24M!C6) -> 208.76419 | D13: =MIN(D12,CAPACITY_24M!D6) -> 209.07061 | E13: =MIN(E12,CAPACITY_24M!E6) -> 209.38214 | F13: =MIN(F12,CAPACITY_24M!F6) -> 209.69887 | G13: =MIN(G12,CAPACITY_24M!G6) -> 210.0209 | H13: =MIN(H12,CAPACITY_24M!H6) -> 210.34833 | I13: =MIN(I12,CAPACITY_24M!I6) -> 210.68126 | ... Y13: =MIN(Y12,CAPACITY_24M!Y6) -> 216.84212
A14: Lost due to sales capacity | B14: =MAX(0,B12-B13) -> 0 | C14: =MAX(0,C12-C13) -> 0 | D14: =MAX(0,D12-D13) -> 0 | E14: =MAX(0,E12-E13) -> 0 | F14: =MAX(0,F12-F13) -> 0 | G14: =MAX(0,G12-G13) -> 0 | H14: =MAX(0,H12-H13) -> 0 | I14: =MAX(0,I12-I13) -> 0 | ... Y14: =MAX(0,Y12-Y13) -> 0
A15: Closed in call | B15: =B13*ASSUMPTIONS!$C$7 -> 87.554376 | C15: =C13*ASSUMPTIONS!$C$7 -> 87.680961 | D15: =D13*ASSUMPTIONS!$C$7 -> 87.809655 | E15: =E13*ASSUMPTIONS!$C$7 -> 87.940497 | F15: =F13*ASSUMPTIONS!$C$7 -> 88.073526 | G15: =G13*ASSUMPTIONS!$C$7 -> 88.20878 | H15: =H13*ASSUMPTIONS!$C$7 -> 88.3463 | I15: =I13*ASSUMPTIONS!$C$7 -> 88.486128 | ... Y15: =Y13*ASSUMPTIONS!$C$7 -> 91.073692
A16: Not closed after call | B16: =B13-B15 -> 120.90842 | C16: =C13-C15 -> 121.08323 | D16: =D13-D15 -> 121.26095 | E16: =E13-E15 -> 121.44164 | F16: =F13-F15 -> 121.62534 | G16: =G13-G15 -> 121.81212 | H16: =H13-H15 -> 122.00203 | I16: =I13-I15 -> 122.19513 | ... Y16: =Y13-Y15 -> 125.76843
A17: Closed by bot | B17: =B16*ASSUMPTIONS!$C$8 -> 26.599853 | C17: =C16*ASSUMPTIONS!$C$8 -> 26.638311 | D17: =D16*ASSUMPTIONS!$C$8 -> 26.677409 | E17: =E16*ASSUMPTIONS!$C$8 -> 26.717161 | F17: =F16*ASSUMPTIONS!$C$8 -> 26.757576 | G17: =G16*ASSUMPTIONS!$C$8 -> 26.798667 | H17: =H16*ASSUMPTIONS!$C$8 -> 26.840447 | I17: =I16*ASSUMPTIONS!$C$8 -> 26.882928 | ... Y17: =Y16*ASSUMPTIONS!$C$8 -> 27.669055
A18: Gross sold cases | B18: =B15+B17 -> 114.15423 | C18: =C15+C17 -> 114.31927 | D18: =D15+D17 -> 114.48706 | E18: =E15+E17 -> 114.65766 | F18: =F15+F17 -> 114.8311 | G18: =G15+G17 -> 115.00745 | H18: =H15+H17 -> 115.18675 | I18: =I15+I17 -> 115.36906 | ... Y18: =Y15+Y17 -> 118.74275
A19: Cancelled cases | B19: =B18*ASSUMPTIONS!$C$9 -> 5.7077115 | C19: =C18*ASSUMPTIONS!$C$9 -> 5.7159636 | D19: =D18*ASSUMPTIONS!$C$9 -> 5.7243532 | E19: =E18*ASSUMPTIONS!$C$9 -> 5.7328829 | F19: =F18*ASSUMPTIONS!$C$9 -> 5.7415551 | G19: =G18*ASSUMPTIONS!$C$9 -> 5.7503724 | H19: =H18*ASSUMPTIONS!$C$9 -> 5.7593374 | I19: =I18*ASSUMPTIONS!$C$9 -> 5.7684528 | ... Y19: =Y18*ASSUMPTIONS!$C$9 -> 5.9371373
A20: Net sold cases | B20: =B18-B19 -> 108.44652 | C20: =C18-C19 -> 108.60331 | D20: =D18-D19 -> 108.76271 | E20: =E18-E19 -> 108.92477 | F20: =F18-F19 -> 109.08955 | G20: =G18-G19 -> 109.25708 | H20: =H18-H19 -> 109.42741 | I20: =I18-I19 -> 109.6006 | ... Y20: =Y18-Y19 -> 112.80561
A22: Avg net price - call | B22: =CASE_TYPES!$B$11 -> 388.25 | C22: =CASE_TYPES!$B$11 -> 388.25 | D22: =CASE_TYPES!$B$11 -> 388.25 | E22: =CASE_TYPES!$B$11 -> 388.25 | F22: =CASE_TYPES!$B$11 -> 388.25 | G22: =CASE_TYPES!$B$11 -> 388.25 | H22: =CASE_TYPES!$B$11 -> 388.25 | I22: =CASE_TYPES!$B$11 -> 388.25 | ... Y22: =CASE_TYPES!$B$11 -> 388.25
A23: Avg net price - bot | B23: =CASE_TYPES!$B$12 -> 359.38 | C23: =CASE_TYPES!$B$12 -> 359.38 | D23: =CASE_TYPES!$B$12 -> 359.38 | E23: =CASE_TYPES!$B$12 -> 359.38 | F23: =CASE_TYPES!$B$12 -> 359.38 | G23: =CASE_TYPES!$B$12 -> 359.38 | H23: =CASE_TYPES!$B$12 -> 359.38 | I23: =CASE_TYPES!$B$12 -> 359.38 | ... Y23: =CASE_TYPES!$B$12 -> 359.38
A24: Gross sold revenue | B24: =B15*B22+B17*B23 -> 43552.442 | C24: =C15*C22+C17*C23 -> 43615.409 | D24: =D15*D22+D17*D23 -> 43679.426 | E24: =E15*E22+E17*E23 -> 43744.511 | F24: =F15*F22+F17*F23 -> 43810.684 | G24: =G15*G22+G17*G23 -> 43877.964 | H24: =H15*H22+H17*H23 -> 43946.371 | I24: =I15*I22+I17*I23 -> 44015.926 | ... Y24: =Y15*Y22+Y17*Y23 -> 45303.066
A25: Cancelled revenue | B25: =B24*ASSUMPTIONS!$C$9 -> 2177.6221 | C25: =C24*ASSUMPTIONS!$C$9 -> 2180.7705 | D25: =D24*ASSUMPTIONS!$C$9 -> 2183.9713 | E25: =E24*ASSUMPTIONS!$C$9 -> 2187.2256 | F25: =F24*ASSUMPTIONS!$C$9 -> 2190.5342 | G25: =G24*ASSUMPTIONS!$C$9 -> 2193.8982 | H25: =H24*ASSUMPTIONS!$C$9 -> 2197.3186 | I25: =I24*ASSUMPTIONS!$C$9 -> 2200.7963 | ... Y25: =Y24*ASSUMPTIONS!$C$9 -> 2265.1533
A26: Net booked revenue | B26: =B24-B25 -> 41374.82 | C26: =C24-C25 -> 41434.639 | D26: =D24-D25 -> 41495.455 | E26: =E24-E25 -> 41557.286 | F26: =F24-F25 -> 41620.15 | G26: =G24-G25 -> 41684.066 | H26: =H24-H25 -> 41749.053 | I26: =I24-I25 -> 41815.13 | ... Y26: =Y24-Y25 -> 43037.913
A28: Lawyer lead acquisition cost | B28: =B6*CHANNELS!$E$5 -> 0 | C28: =C6*CHANNELS!$E$5 -> 0 | D28: =D6*CHANNELS!$E$5 -> 0 | E28: =E6*CHANNELS!$E$5 -> 0 | F28: =F6*CHANNELS!$E$5 -> 0 | G28: =G6*CHANNELS!$E$5 -> 0 | H28: =H6*CHANNELS!$E$5 -> 0 | I28: =I6*CHANNELS!$E$5 -> 0 | ... Y28: =Y6*CHANNELS!$E$5 -> 0
A29: Organic lead acquisition cost | B29: =B7*CHANNELS!$E$6 -> 0 | C29: =C7*CHANNELS!$E$6 -> 0 | D29: =D7*CHANNELS!$E$6 -> 0 | E29: =E7*CHANNELS!$E$6 -> 0 | F29: =F7*CHANNELS!$E$6 -> 0 | G29: =G7*CHANNELS!$E$6 -> 0 | H29: =H7*CHANNELS!$E$6 -> 0 | I29: =I7*CHANNELS!$E$6 -> 0 | ... Y29: =Y7*CHANNELS!$E$6 -> 0
A30: Other partner lead acquisition cost | B30: =B8*CHANNELS!$E$7 -> 0 | C30: =C8*CHANNELS!$E$7 -> 0 | D30: =D8*CHANNELS!$E$7 -> 0 | E30: =E8*CHANNELS!$E$7 -> 0 | F30: =F8*CHANNELS!$E$7 -> 0 | G30: =G8*CHANNELS!$E$7 -> 0 | H30: =H8*CHANNELS!$E$7 -> 0 | I30: =I8*CHANNELS!$E$7 -> 0 | ... Y30: =Y8*CHANNELS!$E$7 -> 0
A31: Total non-ad lead acquisition cost | B31: =SUM(B28:B30) -> 0 | C31: =SUM(C28:C30) -> 0 | D31: =SUM(D28:D30) -> 0 | E31: =SUM(E28:E30) -> 0 | F31: =SUM(F28:F30) -> 0 | G31: =SUM(G28:G30) -> 0 | H31: =SUM(H28:H30) -> 0 | I31: =SUM(I28:I30) -> 0 | ... Y31: =SUM(Y28:Y30) -> 0

Sheet UNIT_ECONOMICS
A1: Economía unitaria por tipo de caso
A3: Tipo | B3: Neto call | C3: Neto bot | D3: Travel cost | E3: IA var | F3: Otros var | G3: Horas base | H3: Horas c/rework | I3: Comisión | J3: Margen contrib. promedio
A4: =CASE_TYPES!A4 -> Simple | B4: =CASE_TYPES!C4*(1-CASE_TYPES!D4) -> 290 | C4: =CASE_TYPES!C4*(1-CASE_TYPES!E4) -> 266.8 | D4: =CASE_TYPES!I4*ASSUMPTIONS!$C$30 -> 11.2 | E4: =CASE_TYPES!J4 -> 6 | F4: =CASE_TYPES!K4 -> 8 | G4: =CASE_TYPES!F4+CASE_TYPES!G4+CASE_TYPES!H4 -> 2.5 | H4: =G4+ASSUMPTIONS!$C$28*ASSUMPTIONS!$C$29 -> 2.564 | I4: =ASSUMPTIONS!$C$16 -> 30 | J4: =((B4*ASSUMPTIONS!$C$7+C4*(1-ASSUMPTIONS!$C$7)*ASSUMPTIONS!$C$8)/(ASSUMPTIONS!$C$7+(1-ASSUMPTIONS!$C$7)*ASSUMPTIONS!$C$8)) - D4-E4-F4-I4 -> 229.39401
A5: =CASE_TYPES!A5 -> Standard | B5: =CASE_TYPES!C5*(1-CASE_TYPES!D5) -> 378.3 | C5: =CASE_TYPES!C5*(1-CASE_TYPES!E5) -> 351 | D5: =CASE_TYPES!I5*ASSUMPTIONS!$C$30 -> 16 | E5: =CASE_TYPES!J5 -> 8 | F5: =CASE_TYPES!K5 -> 12 | G5: =CASE_TYPES!F5+CASE_TYPES!G5+CASE_TYPES!H5 -> 3.3 | H5: =G5+ASSUMPTIONS!$C$28*ASSUMPTIONS!$C$29 -> 3.364 | I5: =ASSUMPTIONS!$C$16 -> 30 | J5: =((B5*ASSUMPTIONS!$C$7+C5*(1-ASSUMPTIONS!$C$7)*ASSUMPTIONS!$C$8)/(ASSUMPTIONS!$C$7+(1-ASSUMPTIONS!$C$7)*ASSUMPTIONS!$C$8)) - D5-E5-F5-I5 -> 305.93864
A6: =CASE_TYPES!A6 -> Complex | B6: =CASE_TYPES!C6*(1-CASE_TYPES!D6) -> 560.5 | C6: =CASE_TYPES!C6*(1-CASE_TYPES!E6) -> 519.2 | D6: =CASE_TYPES!I6*ASSUMPTIONS!$C$30 -> 24 | E6: =CASE_TYPES!J6 -> 12 | F6: =CASE_TYPES!K6 -> 18 | G6: =CASE_TYPES!F6+CASE_TYPES!G6+CASE_TYPES!H6 -> 4.6 | H6: =G6+ASSUMPTIONS!$C$28*ASSUMPTIONS!$C$29 -> 4.664 | I6: =ASSUMPTIONS!$C$16 -> 30 | J6: =((B6*ASSUMPTIONS!$C$7+C6*(1-ASSUMPTIONS!$C$7)*ASSUMPTIONS!$C$8)/(ASSUMPTIONS!$C$7+(1-ASSUMPTIONS!$C$7)*ASSUMPTIONS!$C$8)) - D6-E6-F6-I6 -> 466.87641
A8: Weighted average | B8: =CASE_TYPES!B11 -> 388.25 | C8: =CASE_TYPES!B12 -> 359.38 | D8: =CASE_TYPES!B14*ASSUMPTIONS!$C$30 -> 16.16 | E8: =CASE_TYPES!B15 -> 8.2 | F8: =CASE_TYPES!B16 -> 12 | G8: =CASE_TYPES!B13 -> 3.32 | H8: =G8+ASSUMPTIONS!$C$28*ASSUMPTIONS!$C$29 -> 3.384 | I8: =ASSUMPTIONS!$C$16 -> 30 | J8: =((B8*ASSUMPTIONS!$C$7+C8*(1-ASSUMPTIONS!$C$7)*ASSUMPTIONS!$C$8)/(ASSUMPTIONS!$C$7+(1-ASSUMPTIONS!$C$7)*ASSUMPTIONS!$C$8)) - D8-E8-F8-I8 -> 315.1628

Sheet PNL_24M
A1: Cuenta de resultados mensual (24 meses)
A3: Métrica | B3: M1 | C3: M2 | D3: M3 | E3: M4 | F3: M5 | G3: M6 | H3: M7 | I3: M8 | J3: M9 | K3: M10 | L3: M11 | M3: M12 | N3: M13 | O3: M14 | P3: M15 | Q3: M16 | R3: M17 | S3: M18 | T3: M19 | U3: M20 | V3: M21 | W3: M22 | X3: M23 | Y3: M24
A4: Opening backlog cases | B4: =0 -> 0 | C4: =B9 -> 68.109638 | D4: =C9 -> 136.37607 | E4: =D9 -> 204.8019 | F4: =E9 -> 273.38979 | G4: =F9 -> 342.14246 | H4: =G9 -> 411.06266 | I4: =H9 -> 480.15319 | J4: =I9 -> 549.41691 | ... Y4: =X9 -> 1611.2657
A5: Net sold cases | B5: =FUNNEL_24M!B20 -> 108.44652 | C5: =FUNNEL_24M!C20 -> 108.60331 | D5: =FUNNEL_24M!D20 -> 108.76271 | E5: =FUNNEL_24M!E20 -> 108.92477 | F5: =FUNNEL_24M!F20 -> 109.08955 | G5: =FUNNEL_24M!G20 -> 109.25708 | H5: =FUNNEL_24M!H20 -> 109.42741 | I5: =FUNNEL_24M!I20 -> 109.6006 | ... Y5: =FUNNEL_24M!Y20 -> 112.80561
A6: Cases available to deliver | B6: =B4+B5 -> 108.44652 | C6: =C4+C5 -> 176.71295 | D6: =D4+D5 -> 245.13878 | E6: =E4+E5 -> 313.72667 | F6: =F4+F5 -> 382.47934 | G6: =G4+G5 -> 451.39954 | H6: =H4+H5 -> 520.49007 | I6: =I4+I5 -> 589.75379 | ... Y6: =Y4+Y5 -> 1724.0714
A7: Perito capacity | B7: =CAPACITY_24M!B12 -> 40.336879 | C7: =CAPACITY_24M!C12 -> 40.336879 | D7: =CAPACITY_24M!D12 -> 40.336879 | E7: =CAPACITY_24M!E12 -> 40.336879 | F7: =CAPACITY_24M!F12 -> 40.336879 | G7: =CAPACITY_24M!G12 -> 40.336879 | H7: =CAPACITY_24M!H12 -> 40.336879 | I7: =CAPACITY_24M!I12 -> 40.336879 | ... Y7: =CAPACITY_24M!Y12 -> 40.336879
A8: Delivered cases | B8: =MIN(B6,B7) -> 40.336879 | C8: =MIN(C6,C7) -> 40.336879 | D8: =MIN(D6,D7) -> 40.336879 | E8: =MIN(E6,E7) -> 40.336879 | F8: =MIN(F6,F7) -> 40.336879 | G8: =MIN(G6,G7) -> 40.336879 | H8: =MIN(H6,H7) -> 40.336879 | I8: =MIN(I6,I7) -> 40.336879 | ... Y8: =MIN(Y6,Y7) -> 40.336879
A9: Closing backlog cases | B9: =MAX(0,B6-B8) -> 68.109638 | C9: =MAX(0,C6-C8) -> 136.37607 | D9: =MAX(0,D6-D8) -> 204.8019 | E9: =MAX(0,E6-E8) -> 273.38979 | F9: =MAX(0,F6-F8) -> 342.14246 | G9: =MAX(0,G6-G8) -> 411.06266 | H9: =MAX(0,H6-H8) -> 480.15319 | I9: =MAX(0,I6-I8) -> 549.41691 | ... Y9: =MAX(0,Y6-Y8) -> 1683.7345
A11: Recognized revenue | B11: =IF(FUNNEL_24M!B20=0,0,B8*(FUNNEL_24M!B26/FUNNEL_24M!B20)) -> 15389.439 | C11: =IF(FUNNEL_24M!C20=0,0,C8*(FUNNEL_24M!C26/FUNNEL_24M!C20)) -> 15389.439 | D11: =IF(FUNNEL_24M!D20=0,0,D8*(FUNNEL_24M!D26/FUNNEL_24M!D20)) -> 15389.439 | E11: =IF(FUNNEL_24M!E20=0,0,E8*(FUNNEL_24M!E26/FUNNEL_24M!E20)) -> 15389.439 | F11: =IF(FUNNEL_24M!F20=0,0,F8*(FUNNEL_24M!F26/FUNNEL_24M!F20)) -> 15389.439 | G11: =IF(FUNNEL_24M!G20=0,0,G8*(FUNNEL_24M!G26/FUNNEL_24M!G20)) -> 15389.439 | H11: =IF(FUNNEL_24M!H20=0,0,H8*(FUNNEL_24M!H26/FUNNEL_24M!H20)) -> 15389.439 | I11: =IF(FUNNEL_24M!I20=0,0,I8*(FUNNEL_24M!I26/FUNNEL_24M!I20)) -> 15389.439 | ... Y11: =IF(FUNNEL_24M!Y20=0,0,Y8*(FUNNEL_24M!Y26/FUNNEL_24M!Y20)) -> 15389.439
A12: Travel cost | B12: =B8*CASE_TYPES!$B$14*ASSUMPTIONS!$C$30 -> 651.84397 | C12: =C8*CASE_TYPES!$B$14*ASSUMPTIONS!$C$30 -> 651.84397 | D12: =D8*CASE_TYPES!$B$14*ASSUMPTIONS!$C$30 -> 651.84397 | E12: =E8*CASE_TYPES!$B$14*ASSUMPTIONS!$C$30 -> 651.84397 | F12: =F8*CASE_TYPES!$B$14*ASSUMPTIONS!$C$30 -> 651.84397 | G12: =G8*CASE_TYPES!$B$14*ASSUMPTIONS!$C$30 -> 651.84397 | H12: =H8*CASE_TYPES!$B$14*ASSUMPTIONS!$C$30 -> 651.84397 | I12: =I8*CASE_TYPES!$B$14*ASSUMPTIONS!$C$30 -> 651.84397 | ... Y12: =Y8*CASE_TYPES!$B$14*ASSUMPTIONS!$C$30 -> 651.84397
A13: AI variable cost | B13: =B8*CASE_TYPES!$B$15 -> 330.76241 | C13: =C8*CASE_TYPES!$B$15 -> 330.76241 | D13: =D8*CASE_TYPES!$B$15 -> 330.76241 | E13: =E8*CASE_TYPES!$B$15 -> 330.76241 | F13: =F8*CASE_TYPES!$B$15 -> 330.76241 | G13: =G8*CASE_TYPES!$B$15 -> 330.76241 | H13: =H8*CASE_TYPES!$B$15 -> 330.76241 | I13: =I8*CASE_TYPES!$B$15 -> 330.76241 | ... Y13: =Y8*CASE_TYPES!$B$15 -> 330.76241
A14: Other variable delivery cost | B14: =B8*CASE_TYPES!$B$16 -> 484.04255 | C14: =C8*CASE_TYPES!$B$16 -> 484.04255 | D14: =D8*CASE_TYPES!$B$16 -> 484.04255 | E14: =E8*CASE_TYPES!$B$16 -> 484.04255 | F14: =F8*CASE_TYPES!$B$16 -> 484.04255 | G14: =G8*CASE_TYPES!$B$16 -> 484.04255 | H14: =H8*CASE_TYPES!$B$16 -> 484.04255 | I14: =I8*CASE_TYPES!$B$16 -> 484.04255 | ... Y14: =Y8*CASE_TYPES!$B$16 -> 484.04255
A15: Payment processing | B15: =FUNNEL_24M!B26*ASSUMPTIONS!$C$13 -> 620.62229 | C15: =FUNNEL_24M!C26*ASSUMPTIONS!$C$13 -> 621.51958 | D15: =FUNNEL_24M!D26*ASSUMPTIONS!$C$13 -> 622.43182 | E15: =FUNNEL_24M!E26*ASSUMPTIONS!$C$13 -> 623.35928 | F15: =FUNNEL_24M!F26*ASSUMPTIONS!$C$13 -> 624.30225 | G15: =FUNNEL_24M!G26*ASSUMPTIONS!$C$13 -> 625.26099 | H15: =FUNNEL_24M!H26*ASSUMPTIONS!$C$13 -> 626.23579 | I15: =FUNNEL_24M!I26*ASSUMPTIONS!$C$13 -> 627.22694 | ... Y15: =FUNNEL_24M!Y26*ASSUMPTIONS!$C$13 -> 645.56869
A16: Closer commissions | B16: =FUNNEL_24M!B18*ASSUMPTIONS!$C$16 -> 3424.6269 | C16: =FUNNEL_24M!C18*ASSUMPTIONS!$C$16 -> 3429.5781 | D16: =FUNNEL_24M!D18*ASSUMPTIONS!$C$16 -> 3434.6119 | E16: =FUNNEL_24M!E18*ASSUMPTIONS!$C$16 -> 3439.7297 | F16: =FUNNEL_24M!F18*ASSUMPTIONS!$C$16 -> 3444.933 | G16: =FUNNEL_24M!G18*ASSUMPTIONS!$C$16 -> 3450.2234 | H16: =FUNNEL_24M!H18*ASSUMPTIONS!$C$16 -> 3455.6024 | I16: =FUNNEL_24M!I18*ASSUMPTIONS!$C$16 -> 3461.0717 | ... Y16: =FUNNEL_24M!Y18*ASSUMPTIONS!$C$16 -> 3562.2824
A17: Total direct variable cost | B17: =SUM(B12:B16) -> 5511.8981 | C17: =SUM(C12:C16) -> 5517.7467 | D17: =SUM(D12:D16) -> 5523.6927 | E17: =SUM(E12:E16) -> 5529.738 | F17: =SUM(F12:F16) -> 5535.8842 | G17: =SUM(G12:G16) -> 5542.1333 | H17: =SUM(H12:H16) -> 5548.4872 | I17: =SUM(I12:I16) -> 5554.9476 | ... Y17: =SUM(Y12:Y16) -> 5674.5
A18: Gross profit | B18: =B11-B17 -> 9877.5413 | C18: =C11-C17 -> 9871.6927 | D18: =D11-D17 -> 9865.7467 | E18: =E11-E17 -> 9859.7014 | F18: =F11-F17 -> 9853.5552 | G18: =G11-G17 -> 9847.306 | H18: =H11-H17 -> 9840.9522 | I18: =I11-I17 -> 9834.4918 | ... Y18: =Y11-Y17 -> 9714.9394
A20: Paid social spend | B20: =FUNNEL_24M!B4 -> 6000 | C20: =FUNNEL_24M!C4 -> 6000 | D20: =FUNNEL_24M!D4 -> 6000 | E20: =FUNNEL_24M!E4 -> 6000 | F20: =FUNNEL_24M!F4 -> 6000 | G20: =FUNNEL_24M!G4 -> 6000 | H20: =FUNNEL_24M!H4 -> 6000 | I20: =FUNNEL_24M!I4 -> 6000 | ... Y20: =FUNNEL_24M!Y4 -> 6000
A21: Lawyer lead acquisition cost | B21: =FUNNEL_24M!B28 -> 0 | C21: =FUNNEL_24M!C28 -> 0 | D21: =FUNNEL_24M!D28 -> 0 | E21: =FUNNEL_24M!E28 -> 0 | F21: =FUNNEL_24M!F28 -> 0 | G21: =FUNNEL_24M!G28 -> 0 | H21: =FUNNEL_24M!H28 -> 0 | I21: =FUNNEL_24M!I28 -> 0 | ... Y21: =FUNNEL_24M!Y28 -> 0
A22: Organic lead acquisition cost | B22: =FUNNEL_24M!B29 -> 0 | C22: =FUNNEL_24M!C29 -> 0 | D22: =FUNNEL_24M!D29 -> 0 | E22: =FUNNEL_24M!E29 -> 0 | F22: =FUNNEL_24M!F29 -> 0 | G22: =FUNNEL_24M!G29 -> 0 | H22: =FUNNEL_24M!H29 -> 0 | I22: =FUNNEL_24M!I29 -> 0 | ... Y22: =FUNNEL_24M!Y29 -> 0
A23: Other partner acquisition cost | B23: =FUNNEL_24M!B30 -> 0 | C23: =FUNNEL_24M!C30 -> 0 | D23: =FUNNEL_24M!D30 -> 0 | E23: =FUNNEL_24M!E30 -> 0 | F23: =FUNNEL_24M!F30 -> 0 | G23: =FUNNEL_24M!G30 -> 0 | H23: =FUNNEL_24M!H30 -> 0 | I23: =FUNNEL_24M!I30 -> 0 | ... Y23: =FUNNEL_24M!Y30 -> 0
A24: Total acquisition spend | B24: =SUM(B20:B23) -> 6000 | C24: =SUM(C20:C23) -> 6000 | D24: =SUM(D20:D23) -> 6000 | E24: =SUM(E20:E23) -> 6000 | F24: =SUM(F20:F23) -> 6000 | G24: =SUM(G20:G23) -> 6000 | H24: =SUM(H20:H23) -> 6000 | I24: =SUM(I20:I23) -> 6000 | ... Y24: =SUM(Y20:Y23) -> 6000
A26: Closer salary | B26: =ASSUMPTIONS!$C$14*ASSUMPTIONS!$C$15*(1+ASSUMPTIONS!$C$37)^INT((1-1)/12) -> 0 | C26: =ASSUMPTIONS!$C$14*ASSUMPTIONS!$C$15*(1+ASSUMPTIONS!$C$37)^INT((2-1)/12) -> 0 | D26: =ASSUMPTIONS!$C$14*ASSUMPTIONS!$C$15*(1+ASSUMPTIONS!$C$37)^INT((3-1)/12) -> 0 | E26: =ASSUMPTIONS!$C$14*ASSUMPTIONS!$C$15*(1+ASSUMPTIONS!$C$37)^INT((4-1)/12) -> 0 | F26: =ASSUMPTIONS!$C$14*ASSUMPTIONS!$C$15*(1+ASSUMPTIONS!$C$37)^INT((5-1)/12) -> 0 | G26: =ASSUMPTIONS!$C$14*ASSUMPTIONS!$C$15*(1+ASSUMPTIONS!$C$37)^INT((6-1)/12) -> 0 | H26: =ASSUMPTIONS!$C$14*ASSUMPTIONS!$C$15*(1+ASSUMPTIONS!$C$37)^INT((7-1)/12) -> 0 | I26: =ASSUMPTIONS!$C$14*ASSUMPTIONS!$C$15*(1+ASSUMPTIONS!$C$37)^INT((8-1)/12) -> 0 | J26: =ASSUMPTIONS!$C$14*ASSUMPTIONS!$C$15*(1+ASSUMPTIONS!$C$37)^INT((9-1)/12) -> 0 | K26: =ASSUMPTIONS!$C$14*ASSUMPTIONS!$C$15*(1+ASSUMPTIONS!$C$37)^INT((10-1)/12) -> 0 | L26: =ASSUMPTIONS!$C$14*ASSUMPTIONS!$C$15*(1+ASSUMPTIONS!$C$37)^INT((11-1)/12) -> 0 | M26: =ASSUMPTIONS!$C$14*ASSUMPTIONS!$C$15*(1+ASSUMPTIONS!$C$37)^INT((12-1)/12) -> 0 | N26: =ASSUMPTIONS!$C$14*ASSUMPTIONS!$C$15*(1+ASSUMPTIONS!$C$37)^INT((13-1)/12) -> 0 | O26: =ASSUMPTIONS!$C$14*ASSUMPTIONS!$C$15*(1+ASSUMPTIONS!$C$37)^INT((14-1)/12) -> 0 | P26: =ASSUMPTIONS!$C$14*ASSUMPTIONS!$C$15*(1+ASSUMPTIONS!$C$37)^INT((15-1)/12) -> 0 | Q26: =ASSUMPTIONS!$C$14*ASSUMPTIONS!$C$15*(1+ASSUMPTIONS!$C$37)^INT((16-1)/12) -> 0 | R26: =ASSUMPTIONS!$C$14*ASSUMPTIONS!$C$15*(1+ASSUMPTIONS!$C$37)^INT((17-1)/12) -> 0 | S26: =ASSUMPTIONS!$C$14*ASSUMPTIONS!$C$15*(1+ASSUMPTIONS!$C$37)^INT((18-1)/12) -> 0 | T26: =ASSUMPTIONS!$C$14*ASSUMPTIONS!$C$15*(1+ASSUMPTIONS!$C$37)^INT((19-1)/12) -> 0 | U26: =ASSUMPTIONS!$C$14*ASSUMPTIONS!$C$15*(1+ASSUMPTIONS!$C$37)^INT((20-1)/12) -> 0 | V26: =ASSUMPTIONS!$C$14*ASSUMPTIONS!$C$15*(1+ASSUMPTIONS!$C$37)^INT((21-1)/12) -> 0 | W26: =ASSUMPTIONS!$C$14*ASSUMPTIONS!$C$15*(1+ASSUMPTIONS!$C$37)^INT((22-1)/12) -> 0 | X26: =ASSUMPTIONS!$C$14*ASSUMPTIONS!$C$15*(1+ASSUMPTIONS!$C$37)^INT((23-1)/12) -> 0 | Y26: =ASSUMPTIONS!$C$14*ASSUMPTIONS!$C$15*(1+ASSUMPTIONS!$C$37)^INT((24-1)/12) -> 0
A27: Perito salary | B27: =ASSUMPTIONS!$C$22*ASSUMPTIONS!$C$23*(1+ASSUMPTIONS!$C$37)^INT((1-1)/12) -> 0 | C27: =ASSUMPTIONS!$C$22*ASSUMPTIONS!$C$23*(1+ASSUMPTIONS!$C$37)^INT((2-1)/12) -> 0 | D27: =ASSUMPTIONS!$C$22*ASSUMPTIONS!$C$23*(1+ASSUMPTIONS!$C$37)^INT((3-1)/12) -> 0 | E27: =ASSUMPTIONS!$C$22*ASSUMPTIONS!$C$23*(1+ASSUMPTIONS!$C$37)^INT((4-1)/12) -> 0 | F27: =ASSUMPTIONS!$C$22*ASSUMPTIONS!$C$23*(1+ASSUMPTIONS!$C$37)^INT((5-1)/12) -> 0 | G27: =ASSUMPTIONS!$C$22*ASSUMPTIONS!$C$23*(1+ASSUMPTIONS!$C$37)^INT((6-1)/12) -> 0 | H27: =ASSUMPTIONS!$C$22*ASSUMPTIONS!$C$23*(1+ASSUMPTIONS!$C$37)^INT((7-1)/12) -> 0 | I27: =ASSUMPTIONS!$C$22*ASSUMPTIONS!$C$23*(1+ASSUMPTIONS!$C$37)^INT((8-1)/12) -> 0 | J27: =ASSUMPTIONS!$C$22*ASSUMPTIONS!$C$23*(1+ASSUMPTIONS!$C$37)^INT((9-1)/12) -> 0 | K27: =ASSUMPTIONS!$C$22*ASSUMPTIONS!$C$23*(1+ASSUMPTIONS!$C$37)^INT((10-1)/12) -> 0 | L27: =ASSUMPTIONS!$C$22*ASSUMPTIONS!$C$23*(1+ASSUMPTIONS!$C$37)^INT((11-1)/12) -> 0 | M27: =ASSUMPTIONS!$C$22*ASSUMPTIONS!$C$23*(1+ASSUMPTIONS!$C$37)^INT((12-1)/12) -> 0 | N27: =ASSUMPTIONS!$C$22*ASSUMPTIONS!$C$23*(1+ASSUMPTIONS!$C$37)^INT((13-1)/12) -> 0 | O27: =ASSUMPTIONS!$C$22*ASSUMPTIONS!$C$23*(1+ASSUMPTIONS!$C$37)^INT((14-1)/12) -> 0 | P27: =ASSUMPTIONS!$C$22*ASSUMPTIONS!$C$23*(1+ASSUMPTIONS!$C$37)^INT((15-1)/12) -> 0 | Q27: =ASSUMPTIONS!$C$22*ASSUMPTIONS!$C$23*(1+ASSUMPTIONS!$C$37)^INT((16-1)/12) -> 0 | R27: =ASSUMPTIONS!$C$22*ASSUMPTIONS!$C$23*(1+ASSUMPTIONS!$C$37)^INT((17-1)/12) -> 0 | S27: =ASSUMPTIONS!$C$22*ASSUMPTIONS!$C$23*(1+ASSUMPTIONS!$C$37)^INT((18-1)/12) -> 0 | T27: =ASSUMPTIONS!$C$22*ASSUMPTIONS!$C$23*(1+ASSUMPTIONS!$C$37)^INT((19-1)/12) -> 0 | U27: =ASSUMPTIONS!$C$22*ASSUMPTIONS!$C$23*(1+ASSUMPTIONS!$C$37)^INT((20-1)/12) -> 0 | V27: =ASSUMPTIONS!$C$22*ASSUMPTIONS!$C$23*(1+ASSUMPTIONS!$C$37)^INT((21-1)/12) -> 0 | W27: =ASSUMPTIONS!$C$22*ASSUMPTIONS!$C$23*(1+ASSUMPTIONS!$C$37)^INT((22-1)/12) -> 0 | X27: =ASSUMPTIONS!$C$22*ASSUMPTIONS!$C$23*(1+ASSUMPTIONS!$C$37)^INT((23-1)/12) -> 0 | Y27: =ASSUMPTIONS!$C$22*ASSUMPTIONS!$C$23*(1+ASSUMPTIONS!$C$37)^INT((24-1)/12) -> 0
A28: Perito renting | B28: =ASSUMPTIONS!$C$22*ASSUMPTIONS!$C$24*(1+ASSUMPTIONS!$C$37)^INT((1-1)/12) -> 450 | C28: =ASSUMPTIONS!$C$22*ASSUMPTIONS!$C$24*(1+ASSUMPTIONS!$C$37)^INT((2-1)/12) -> 450 | D28: =ASSUMPTIONS!$C$22*ASSUMPTIONS!$C$24*(1+ASSUMPTIONS!$C$37)^INT((3-1)/12) -> 450 | E28: =ASSUMPTIONS!$C$22*ASSUMPTIONS!$C$24*(1+ASSUMPTIONS!$C$37)^INT((4-1)/12) -> 450 | F28: =ASSUMPTIONS!$C$22*ASSUMPTIONS!$C$24*(1+ASSUMPTIONS!$C$37)^INT((5-1)/12) -> 450 | G28: =ASSUMPTIONS!$C$22*ASSUMPTIONS!$C$24*(1+ASSUMPTIONS!$C$37)^INT((6-1)/12) -> 450 | H28: =ASSUMPTIONS!$C$22*ASSUMPTIONS!$C$24*(1+ASSUMPTIONS!$C$37)^INT((7-1)/12) -> 450 | I28: =ASSUMPTIONS!$C$22*ASSUMPTIONS!$C$24*(1+ASSUMPTIONS!$C$37)^INT((8-1)/12) -> 450 | J28: =ASSUMPTIONS!$C$22*ASSUMPTIONS!$C$24*(1+ASSUMPTIONS!$C$37)^INT((9-1)/12) -> 450 | K28: =ASSUMPTIONS!$C$22*ASSUMPTIONS!$C$24*(1+ASSUMPTIONS!$C$37)^INT((10-1)/12) -> 450 | L28: =ASSUMPTIONS!$C$22*ASSUMPTIONS!$C$24*(1+ASSUMPTIONS!$C$37)^INT((11-1)/12) -> 450 | M28: =ASSUMPTIONS!$C$22*ASSUMPTIONS!$C$24*(1+ASSUMPTIONS!$C$37)^INT((12-1)/12) -> 450 | N28: =ASSUMPTIONS!$C$22*ASSUMPTIONS!$C$24*(1+ASSUMPTIONS!$C$37)^INT((13-1)/12) -> 463.5 | O28: =ASSUMPTIONS!$C$22*ASSUMPTIONS!$C$24*(1+ASSUMPTIONS!$C$37)^INT((14-1)/12) -> 463.5 | P28: =ASSUMPTIONS!$C$22*ASSUMPTIONS!$C$24*(1+ASSUMPTIONS!$C$37)^INT((15-1)/12) -> 463.5 | Q28: =ASSUMPTIONS!$C$22*ASSUMPTIONS!$C$24*(1+ASSUMPTIONS!$C$37)^INT((16-1)/12) -> 463.5 | R28: =ASSUMPTIONS!$C$22*ASSUMPTIONS!$C$24*(1+ASSUMPTIONS!$C$37)^INT((17-1)/12) -> 463.5 | S28: =ASSUMPTIONS!$C$22*ASSUMPTIONS!$C$24*(1+ASSUMPTIONS!$C$37)^INT((18-1)/12) -> 463.5 | T28: =ASSUMPTIONS!$C$22*ASSUMPTIONS!$C$24*(1+ASSUMPTIONS!$C$37)^INT((19-1)/12) -> 463.5 | U28: =ASSUMPTIONS!$C$22*ASSUMPTIONS!$C$24*(1+ASSUMPTIONS!$C$37)^INT((20-1)/12) -> 463.5 | V28: =ASSUMPTIONS!$C$22*ASSUMPTIONS!$C$24*(1+ASSUMPTIONS!$C$37)^INT((21-1)/12) -> 463.5 | W28: =ASSUMPTIONS!$C$22*ASSUMPTIONS!$C$24*(1+ASSUMPTIONS!$C$37)^INT((22-1)/12) -> 463.5 | X28: =ASSUMPTIONS!$C$22*ASSUMPTIONS!$C$24*(1+ASSUMPTIONS!$C$37)^INT((23-1)/12) -> 463.5 | Y28: =ASSUMPTIONS!$C$22*ASSUMPTIONS!$C$24*(1+ASSUMPTIONS!$C$37)^INT((24-1)/12) -> 463.5
A29: Perito phone+laptop | B29: =ASSUMPTIONS!$C$22*ASSUMPTIONS!$C$25*(1+ASSUMPTIONS!$C$37)^INT((1-1)/12) -> 90 | C29: =ASSUMPTIONS!$C$22*ASSUMPTIONS!$C$25*(1+ASSUMPTIONS!$C$37)^INT((2-1)/12) -> 90 | D29: =ASSUMPTIONS!$C$22*ASSUMPTIONS!$C$25*(1+ASSUMPTIONS!$C$37)^INT((3-1)/12) -> 90 | E29: =ASSUMPTIONS!$C$22*ASSUMPTIONS!$C$25*(1+ASSUMPTIONS!$C$37)^INT((4-1)/12) -> 90 | F29: =ASSUMPTIONS!$C$22*ASSUMPTIONS!$C$25*(1+ASSUMPTIONS!$C$37)^INT((5-1)/12) -> 90 | G29: =ASSUMPTIONS!$C$22*ASSUMPTIONS!$C$25*(1+ASSUMPTIONS!$C$37)^INT((6-1)/12) -> 90 | H29: =ASSUMPTIONS!$C$22*ASSUMPTIONS!$C$25*(1+ASSUMPTIONS!$C$37)^INT((7-1)/12) -> 90 | I29: =ASSUMPTIONS!$C$22*ASSUMPTIONS!$C$25*(1+ASSUMPTIONS!$C$37)^INT((8-1)/12) -> 90 | J29: =ASSUMPTIONS!$C$22*ASSUMPTIONS!$C$25*(1+ASSUMPTIONS!$C$37)^INT((9-1)/12) -> 90 | K29: =ASSUMPTIONS!$C$22*ASSUMPTIONS!$C$25*(1+ASSUMPTIONS!$C$37)^INT((10-1)/12) -> 90 | L29: =ASSUMPTIONS!$C$22*ASSUMPTIONS!$C$25*(1+ASSUMPTIONS!$C$37)^INT((11-1)/12) -> 90 | M29: =ASSUMPTIONS!$C$22*ASSUMPTIONS!$C$25*(1+ASSUMPTIONS!$C$37)^INT((12-1)/12) -> 90 | N29: =ASSUMPTIONS!$C$22*ASSUMPTIONS!$C$25*(1+ASSUMPTIONS!$C$37)^INT((13-1)/12) -> 92.7 | O29: =ASSUMPTIONS!$C$22*ASSUMPTIONS!$C$25*(1+ASSUMPTIONS!$C$37)^INT((14-1)/12) -> 92.7 | P29: =ASSUMPTIONS!$C$22*ASSUMPTIONS!$C$25*(1+ASSUMPTIONS!$C$37)^INT((15-1)/12) -> 92.7 | Q29: =ASSUMPTIONS!$C$22*ASSUMPTIONS!$C$25*(1+ASSUMPTIONS!$C$37)^INT((16-1)/12) -> 92.7 | R29: =ASSUMPTIONS!$C$22*ASSUMPTIONS!$C$25*(1+ASSUMPTIONS!$C$37)^INT((17-1)/12) -> 92.7 | S29: =ASSUMPTIONS!$C$22*ASSUMPTIONS!$C$25*(1+ASSUMPTIONS!$C$37)^INT((18-1)/12) -> 92.7 | T29: =ASSUMPTIONS!$C$22*ASSUMPTIONS!$C$25*(1+ASSUMPTIONS!$C$37)^INT((19-1)/12) -> 92.7 | U29: =ASSUMPTIONS!$C$22*ASSUMPTIONS!$C$25*(1+ASSUMPTIONS!$C$37)^INT((20-1)/12) -> 92.7 | V29: =ASSUMPTIONS!$C$22*ASSUMPTIONS!$C$25*(1+ASSUMPTIONS!$C$37)^INT((21-1)/12) -> 92.7 | W29: =ASSUMPTIONS!$C$22*ASSUMPTIONS!$C$25*(1+ASSUMPTIONS!$C$37)^INT((22-1)/12) -> 92.7 | X29: =ASSUMPTIONS!$C$22*ASSUMPTIONS!$C$25*(1+ASSUMPTIONS!$C$37)^INT((23-1)/12) -> 92.7 | Y29: =ASSUMPTIONS!$C$22*ASSUMPTIONS!$C$25*(1+ASSUMPTIONS!$C$37)^INT((24-1)/12) -> 92.7
A30: Founder / GM salary | B30: =ASSUMPTIONS!$C$31*(1+ASSUMPTIONS!$C$37)^INT((1-1)/12) -> 0 | C30: =ASSUMPTIONS!$C$31*(1+ASSUMPTIONS!$C$37)^INT((2-1)/12) -> 0 | D30: =ASSUMPTIONS!$C$31*(1+ASSUMPTIONS!$C$37)^INT((3-1)/12) -> 0 | E30: =ASSUMPTIONS!$C$31*(1+ASSUMPTIONS!$C$37)^INT((4-1)/12) -> 0 | F30: =ASSUMPTIONS!$C$31*(1+ASSUMPTIONS!$C$37)^INT((5-1)/12) -> 0 | G30: =ASSUMPTIONS!$C$31*(1+ASSUMPTIONS!$C$37)^INT((6-1)/12) -> 0 | H30: =ASSUMPTIONS!$C$31*(1+ASSUMPTIONS!$C$37)^INT((7-1)/12) -> 0 | I30: =ASSUMPTIONS!$C$31*(1+ASSUMPTIONS!$C$37)^INT((8-1)/12) -> 0 | J30: =ASSUMPTIONS!$C$31*(1+ASSUMPTIONS!$C$37)^INT((9-1)/12) -> 0 | K30: =ASSUMPTIONS!$C$31*(1+ASSUMPTIONS!$C$37)^INT((10-1)/12) -> 0 | L30: =ASSUMPTIONS!$C$31*(1+ASSUMPTIONS!$C$37)^INT((11-1)/12) -> 0 | M30: =ASSUMPTIONS!$C$31*(1+ASSUMPTIONS!$C$37)^INT((12-1)/12) -> 0 | N30: =ASSUMPTIONS!$C$31*(1+ASSUMPTIONS!$C$37)^INT((13-1)/12) -> 0 | O30: =ASSUMPTIONS!$C$31*(1+ASSUMPTIONS!$C$37)^INT((14-1)/12) -> 0 | P30: =ASSUMPTIONS!$C$31*(1+ASSUMPTIONS!$C$37)^INT((15-1)/12) -> 0 | Q30: =ASSUMPTIONS!$C$31*(1+ASSUMPTIONS!$C$37)^INT((16-1)/12) -> 0 | R30: =ASSUMPTIONS!$C$31*(1+ASSUMPTIONS!$C$37)^INT((17-1)/12) -> 0 | S30: =ASSUMPTIONS!$C$31*(1+ASSUMPTIONS!$C$37)^INT((18-1)/12) -> 0 | T30: =ASSUMPTIONS!$C$31*(1+ASSUMPTIONS!$C$37)^INT((19-1)/12) -> 0 | U30: =ASSUMPTIONS!$C$31*(1+ASSUMPTIONS!$C$37)^INT((20-1)/12) -> 0 | V30: =ASSUMPTIONS!$C$31*(1+ASSUMPTIONS!$C$37)^INT((21-1)/12) -> 0 | W30: =ASSUMPTIONS!$C$31*(1+ASSUMPTIONS!$C$37)^INT((22-1)/12) -> 0 | X30: =ASSUMPTIONS!$C$31*(1+ASSUMPTIONS!$C$37)^INT((23-1)/12) -> 0 | Y30: =ASSUMPTIONS!$C$31*(1+ASSUMPTIONS!$C$37)^INT((24-1)/12) -> 0
A31: Agency retainer | B31: =ASSUMPTIONS!$C$32*(1+ASSUMPTIONS!$C$37)^INT((1-1)/12) -> 1200 | C31: =ASSUMPTIONS!$C$32*(1+ASSUMPTIONS!$C$37)^INT((2-1)/12) -> 1200 | D31: =ASSUMPTIONS!$C$32*(1+ASSUMPTIONS!$C$37)^INT((3-1)/12) -> 1200 | E31: =ASSUMPTIONS!$C$32*(1+ASSUMPTIONS!$C$37)^INT((4-1)/12) -> 1200 | F31: =ASSUMPTIONS!$C$32*(1+ASSUMPTIONS!$C$37)^INT((5-1)/12) -> 1200 | G31: =ASSUMPTIONS!$C$32*(1+ASSUMPTIONS!$C$37)^INT((6-1)/12) -> 1200 | H31: =ASSUMPTIONS!$C$32*(1+ASSUMPTIONS!$C$37)^INT((7-1)/12) -> 1200 | I31: =ASSUMPTIONS!$C$32*(1+ASSUMPTIONS!$C$37)^INT((8-1)/12) -> 1200 | J31: =ASSUMPTIONS!$C$32*(1+ASSUMPTIONS!$C$37)^INT((9-1)/12) -> 1200 | K31: =ASSUMPTIONS!$C$32*(1+ASSUMPTIONS!$C$37)^INT((10-1)/12) -> 1200 | L31: =ASSUMPTIONS!$C$32*(1+ASSUMPTIONS!$C$37)^INT((11-1)/12) -> 1200 | M31: =ASSUMPTIONS!$C$32*(1+ASSUMPTIONS!$C$37)^INT((12-1)/12) -> 1200 | N31: =ASSUMPTIONS!$C$32*(1+ASSUMPTIONS!$C$37)^INT((13-1)/12) -> 1236 | O31: =ASSUMPTIONS!$C$32*(1+ASSUMPTIONS!$C$37)^INT((14-1)/12) -> 1236 | P31: =ASSUMPTIONS!$C$32*(1+ASSUMPTIONS!$C$37)^INT((15-1)/12) -> 1236 | Q31: =ASSUMPTIONS!$C$32*(1+ASSUMPTIONS!$C$37)^INT((16-1)/12) -> 1236 | R31: =ASSUMPTIONS!$C$32*(1+ASSUMPTIONS!$C$37)^INT((17-1)/12) -> 1236 | S31: =ASSUMPTIONS!$C$32*(1+ASSUMPTIONS!$C$37)^INT((18-1)/12) -> 1236 | T31: =ASSUMPTIONS!$C$32*(1+ASSUMPTIONS!$C$37)^INT((19-1)/12) -> 1236 | U31: =ASSUMPTIONS!$C$32*(1+ASSUMPTIONS!$C$37)^INT((20-1)/12) -> 1236 | V31: =ASSUMPTIONS!$C$32*(1+ASSUMPTIONS!$C$37)^INT((21-1)/12) -> 1236 | W31: =ASSUMPTIONS!$C$32*(1+ASSUMPTIONS!$C$37)^INT((22-1)/12) -> 1236 | X31: =ASSUMPTIONS!$C$32*(1+ASSUMPTIONS!$C$37)^INT((23-1)/12) -> 1236 | Y31: =ASSUMPTIONS!$C$32*(1+ASSUMPTIONS!$C$37)^INT((24-1)/12) -> 1236
A32: General overhead | B32: =ASSUMPTIONS!$C$33*(1+ASSUMPTIONS!$C$37)^INT((1-1)/12) -> 350 | C32: =ASSUMPTIONS!$C$33*(1+ASSUMPTIONS!$C$37)^INT((2-1)/12) -> 350 | D32: =ASSUMPTIONS!$C$33*(1+ASSUMPTIONS!$C$37)^INT((3-1)/12) -> 350 | E32: =ASSUMPTIONS!$C$33*(1+ASSUMPTIONS!$C$37)^INT((4-1)/12) -> 350 | F32: =ASSUMPTIONS!$C$33*(1+ASSUMPTIONS!$C$37)^INT((5-1)/12) -> 350 | G32: =ASSUMPTIONS!$C$33*(1+ASSUMPTIONS!$C$37)^INT((6-1)/12) -> 350 | H32: =ASSUMPTIONS!$C$33*(1+ASSUMPTIONS!$C$37)^INT((7-1)/12) -> 350 | I32: =ASSUMPTIONS!$C$33*(1+ASSUMPTIONS!$C$37)^INT((8-1)/12) -> 350 | J32: =ASSUMPTIONS!$C$33*(1+ASSUMPTIONS!$C$37)^INT((9-1)/12) -> 350 | K32: =ASSUMPTIONS!$C$33*(1+ASSUMPTIONS!$C$37)^INT((10-1)/12) -> 350 | L32: =ASSUMPTIONS!$C$33*(1+ASSUMPTIONS!$C$37)^INT((11-1)/12) -> 350 | M32: =ASSUMPTIONS!$C$33*(1+ASSUMPTIONS!$C$37)^INT((12-1)/12) -> 350 | N32: =ASSUMPTIONS!$C$33*(1+ASSUMPTIONS!$C$37)^INT((13-1)/12) -> 360.5 | O32: =ASSUMPTIONS!$C$33*(1+ASSUMPTIONS!$C$37)^INT((14-1)/12) -> 360.5 | P32: =ASSUMPTIONS!$C$33*(1+ASSUMPTIONS!$C$37)^INT((15-1)/12) -> 360.5 | Q32: =ASSUMPTIONS!$C$33*(1+ASSUMPTIONS!$C$37)^INT((16-1)/12) -> 360.5 | R32: =ASSUMPTIONS!$C$33*(1+ASSUMPTIONS!$C$37)^INT((17-1)/12) -> 360.5 | S32: =ASSUMPTIONS!$C$33*(1+ASSUMPTIONS!$C$37)^INT((18-1)/12) -> 360.5 | T32: =ASSUMPTIONS!$C$33*(1+ASSUMPTIONS!$C$37)^INT((19-1)/12) -> 360.5 | U32: =ASSUMPTIONS!$C$33*(1+ASSUMPTIONS!$C$37)^INT((20-1)/12) -> 360.5 | V32: =ASSUMPTIONS!$C$33*(1+ASSUMPTIONS!$C$37)^INT((21-1)/12) -> 360.5 | W32: =ASSUMPTIONS!$C$33*(1+ASSUMPTIONS!$C$37)^INT((22-1)/12) -> 360.5 | X32: =ASSUMPTIONS!$C$33*(1+ASSUMPTIONS!$C$37)^INT((23-1)/12) -> 360.5 | Y32: =ASSUMPTIONS!$C$33*(1+ASSUMPTIONS!$C$37)^INT((24-1)/12) -> 360.5
A33: Software fixed | B33: =ASSUMPTIONS!$C$34*(1+ASSUMPTIONS!$C$37)^INT((1-1)/12) -> 250 | C33: =ASSUMPTIONS!$C$34*(1+ASSUMPTIONS!$C$37)^INT((2-1)/12) -> 250 | D33: =ASSUMPTIONS!$C$34*(1+ASSUMPTIONS!$C$37)^INT((3-1)/12) -> 250 | E33: =ASSUMPTIONS!$C$34*(1+ASSUMPTIONS!$C$37)^INT((4-1)/12) -> 250 | F33: =ASSUMPTIONS!$C$34*(1+ASSUMPTIONS!$C$37)^INT((5-1)/12) -> 250 | G33: =ASSUMPTIONS!$C$34*(1+ASSUMPTIONS!$C$37)^INT((6-1)/12) -> 250 | H33: =ASSUMPTIONS!$C$34*(1+ASSUMPTIONS!$C$37)^INT((7-1)/12) -> 250 | I33: =ASSUMPTIONS!$C$34*(1+ASSUMPTIONS!$C$37)^INT((8-1)/12) -> 250 | J33: =ASSUMPTIONS!$C$34*(1+ASSUMPTIONS!$C$37)^INT((9-1)/12) -> 250 | K33: =ASSUMPTIONS!$C$34*(1+ASSUMPTIONS!$C$37)^INT((10-1)/12) -> 250 | L33: =ASSUMPTIONS!$C$34*(1+ASSUMPTIONS!$C$37)^INT((11-1)/12) -> 250 | M33: =ASSUMPTIONS!$C$34*(1+ASSUMPTIONS!$C$37)^INT((12-1)/12) -> 250 | N33: =ASSUMPTIONS!$C$34*(1+ASSUMPTIONS!$C$37)^INT((13-1)/12) -> 257.5 | O33: =ASSUMPTIONS!$C$34*(1+ASSUMPTIONS!$C$37)^INT((14-1)/12) -> 257.5 | P33: =ASSUMPTIONS!$C$34*(1+ASSUMPTIONS!$C$37)^INT((15-1)/12) -> 257.5 | Q33: =ASSUMPTIONS!$C$34*(1+ASSUMPTIONS!$C$37)^INT((16-1)/12) -> 257.5 | R33: =ASSUMPTIONS!$C$34*(1+ASSUMPTIONS!$C$37)^INT((17-1)/12) -> 257.5 | S33: =ASSUMPTIONS!$C$34*(1+ASSUMPTIONS!$C$37)^INT((18-1)/12) -> 257.5 | T33: =ASSUMPTIONS!$C$34*(1+ASSUMPTIONS!$C$37)^INT((19-1)/12) -> 257.5 | U33: =ASSUMPTIONS!$C$34*(1+ASSUMPTIONS!$C$37)^INT((20-1)/12) -> 257.5 | V33: =ASSUMPTIONS!$C$34*(1+ASSUMPTIONS!$C$37)^INT((21-1)/12) -> 257.5 | W33: =ASSUMPTIONS!$C$34*(1+ASSUMPTIONS!$C$37)^INT((22-1)/12) -> 257.5 | X33: =ASSUMPTIONS!$C$34*(1+ASSUMPTIONS!$C$37)^INT((23-1)/12) -> 257.5 | Y33: =ASSUMPTIONS!$C$34*(1+ASSUMPTIONS!$C$37)^INT((24-1)/12) -> 257.5
A34: AI platform fixed | B34: =ASSUMPTIONS!$C$35*(1+ASSUMPTIONS!$C$37)^INT((1-1)/12) -> 180 | C34: =ASSUMPTIONS!$C$35*(1+ASSUMPTIONS!$C$37)^INT((2-1)/12) -> 180 | D34: =ASSUMPTIONS!$C$35*(1+ASSUMPTIONS!$C$37)^INT((3-1)/12) -> 180 | E34: =ASSUMPTIONS!$C$35*(1+ASSUMPTIONS!$C$37)^INT((4-1)/12) -> 180 | F34: =ASSUMPTIONS!$C$35*(1+ASSUMPTIONS!$C$37)^INT((5-1)/12) -> 180 | G34: =ASSUMPTIONS!$C$35*(1+ASSUMPTIONS!$C$37)^INT((6-1)/12) -> 180 | H34: =ASSUMPTIONS!$C$35*(1+ASSUMPTIONS!$C$37)^INT((7-1)/12) -> 180 | I34: =ASSUMPTIONS!$C$35*(1+ASSUMPTIONS!$C$37)^INT((8-1)/12) -> 180 | J34: =ASSUMPTIONS!$C$35*(1+ASSUMPTIONS!$C$37)^INT((9-1)/12) -> 180 | K34: =ASSUMPTIONS!$C$35*(1+ASSUMPTIONS!$C$37)^INT((10-1)/12) -> 180 | L34: =ASSUMPTIONS!$C$35*(1+ASSUMPTIONS!$C$37)^INT((11-1)/12) -> 180 | M34: =ASSUMPTIONS!$C$35*(1+ASSUMPTIONS!$C$37)^INT((12-1)/12) -> 180 | N34: =ASSUMPTIONS!$C$35*(1+ASSUMPTIONS!$C$37)^INT((13-1)/12) -> 185.4 | O34: =ASSUMPTIONS!$C$35*(1+ASSUMPTIONS!$C$37)^INT((14-1)/12) -> 185.4 | P34: =ASSUMPTIONS!$C$35*(1+ASSUMPTIONS!$C$37)^INT((15-1)/12) -> 185.4 | Q34: =ASSUMPTIONS!$C$35*(1+ASSUMPTIONS!$C$37)^INT((16-1)/12) -> 185.4 | R34: =ASSUMPTIONS!$C$35*(1+ASSUMPTIONS!$C$37)^INT((17-1)/12) -> 185.4 | S34: =ASSUMPTIONS!$C$35*(1+ASSUMPTIONS!$C$37)^INT((18-1)/12) -> 185.4 | T34: =ASSUMPTIONS!$C$35*(1+ASSUMPTIONS!$C$37)^INT((19-1)/12) -> 185.4 | U34: =ASSUMPTIONS!$C$35*(1+ASSUMPTIONS!$C$37)^INT((20-1)/12) -> 185.4 | V34: =ASSUMPTIONS!$C$35*(1+ASSUMPTIONS!$C$37)^INT((21-1)/12) -> 185.4 | W34: =ASSUMPTIONS!$C$35*(1+ASSUMPTIONS!$C$37)^INT((22-1)/12) -> 185.4 | X34: =ASSUMPTIONS!$C$35*(1+ASSUMPTIONS!$C$37)^INT((23-1)/12) -> 185.4 | Y34: =ASSUMPTIONS!$C$35*(1+ASSUMPTIONS!$C$37)^INT((24-1)/12) -> 185.4
A35: Insurance/legal/admin | B35: =ASSUMPTIONS!$C$36*(1+ASSUMPTIONS!$C$37)^INT((1-1)/12) -> 200 | C35: =ASSUMPTIONS!$C$36*(1+ASSUMPTIONS!$C$37)^INT((2-1)/12) -> 200 | D35: =ASSUMPTIONS!$C$36*(1+ASSUMPTIONS!$C$37)^INT((3-1)/12) -> 200 | E35: =ASSUMPTIONS!$C$36*(1+ASSUMPTIONS!$C$37)^INT((4-1)/12) -> 200 | F35: =ASSUMPTIONS!$C$36*(1+ASSUMPTIONS!$C$37)^INT((5-1)/12) -> 200 | G35: =ASSUMPTIONS!$C$36*(1+ASSUMPTIONS!$C$37)^INT((6-1)/12) -> 200 | H35: =ASSUMPTIONS!$C$36*(1+ASSUMPTIONS!$C$37)^INT((7-1)/12) -> 200 | I35: =ASSUMPTIONS!$C$36*(1+ASSUMPTIONS!$C$37)^INT((8-1)/12) -> 200 | J35: =ASSUMPTIONS!$C$36*(1+ASSUMPTIONS!$C$37)^INT((9-1)/12) -> 200 | K35: =ASSUMPTIONS!$C$36*(1+ASSUMPTIONS!$C$37)^INT((10-1)/12) -> 200 | L35: =ASSUMPTIONS!$C$36*(1+ASSUMPTIONS!$C$37)^INT((11-1)/12) -> 200 | M35: =ASSUMPTIONS!$C$36*(1+ASSUMPTIONS!$C$37)^INT((12-1)/12) -> 200 | N35: =ASSUMPTIONS!$C$36*(1+ASSUMPTIONS!$C$37)^INT((13-1)/12) -> 206 | O35: =ASSUMPTIONS!$C$36*(1+ASSUMPTIONS!$C$37)^INT((14-1)/12) -> 206 | P35: =ASSUMPTIONS!$C$36*(1+ASSUMPTIONS!$C$37)^INT((15-1)/12) -> 206 | Q35: =ASSUMPTIONS!$C$36*(1+ASSUMPTIONS!$C$37)^INT((16-1)/12) -> 206 | R35: =ASSUMPTIONS!$C$36*(1+ASSUMPTIONS!$C$37)^INT((17-1)/12) -> 206 | S35: =ASSUMPTIONS!$C$36*(1+ASSUMPTIONS!$C$37)^INT((18-1)/12) -> 206 | T35: =ASSUMPTIONS!$C$36*(1+ASSUMPTIONS!$C$37)^INT((19-1)/12) -> 206 | U35: =ASSUMPTIONS!$C$36*(1+ASSUMPTIONS!$C$37)^INT((20-1)/12) -> 206 | V35: =ASSUMPTIONS!$C$36*(1+ASSUMPTIONS!$C$37)^INT((21-1)/12) -> 206 | W35: =ASSUMPTIONS!$C$36*(1+ASSUMPTIONS!$C$37)^INT((22-1)/12) -> 206 | X35: =ASSUMPTIONS!$C$36*(1+ASSUMPTIONS!$C$37)^INT((23-1)/12) -> 206 | Y35: =ASSUMPTIONS!$C$36*(1+ASSUMPTIONS!$C$37)^INT((24-1)/12) -> 206
A36: Total fixed OPEX | B36: =SUM(B26:B35) -> 2720 | C36: =SUM(C26:C35) -> 2720 | D36: =SUM(D26:D35) -> 2720 | E36: =SUM(E26:E35) -> 2720 | F36: =SUM(F26:F35) -> 2720 | G36: =SUM(G26:G35) -> 2720 | H36: =SUM(H26:H35) -> 2720 | I36: =SUM(I26:I35) -> 2720 | ... Y36: =SUM(Y26:Y35) -> 2801.6
A38: EBITDA | B38: =B18-B24-B36 -> 1157.5413 | C38: =C18-C24-C36 -> 1151.6927 | D38: =D18-D24-D36 -> 1145.7467 | E38: =E18-E24-E36 -> 1139.7014 | F38: =F18-F24-F36 -> 1133.5552 | G38: =G18-G24-G36 -> 1127.306 | H38: =H18-H24-H36 -> 1120.9522 | I38: =I18-I24-I36 -> 1114.4918 | ... Y38: =Y18-Y24-Y36 -> 913.33936
A39: EBITDA margin | B39: =IF(B11=0,0,B38/B11) -> 0.075216598 | C39: =IF(C11=0,0,C38/C11) -> 0.074836561 | D39: =IF(D11=0,0,D38/D11) -> 0.07445019 | E39: =IF(E11=0,0,E38/E11) -> 0.074057372 | F39: =IF(F11=0,0,F38/F11) -> 0.073657989 | G39: =IF(G11=0,0,G38/G11) -> 0.073251924 | H39: =IF(H11=0,0,H38/H11) -> 0.072839055 | I39: =IF(I11=0,0,I38/I11) -> 0.072419261 | ... Y39: =IF(Y11=0,0,Y38/Y11) -> 0.059348449
A40: Revenue / delivered case | B40: =IF(B8=0,0,B11/B8) -> 381.5228 | C40: =IF(C8=0,0,C11/C8) -> 381.5228 | D40: =IF(D8=0,0,D11/D8) -> 381.5228 | E40: =IF(E8=0,0,E11/E8) -> 381.5228 | F40: =IF(F8=0,0,F11/F8) -> 381.5228 | G40: =IF(G8=0,0,G11/G8) -> 381.5228 | H40: =IF(H8=0,0,H11/H8) -> 381.5228 | I40: =IF(I8=0,0,I11/I8) -> 381.5228 | ... Y40: =IF(Y8=0,0,Y11/Y8) -> 381.5228
A42: Total 24M revenue | B42: =SUM(B11:Y11) -> 369346.55
A43: Total 24M EBITDA | B43: =SUM(B38:Y38) -> 24970.155
A44: Avg monthly EBITDA | B44: =AVERAGE(B38:Y38) -> 1040.4231
A45: Max backlog | B45: =MAX(B9:Y9) -> 1683.7345

Sheet CASHFLOW_24M
A1: Caja mensual (24 meses)
A3: Métrica | B3: M1 | C3: M2 | D3: M3 | E3: M4 | F3: M5 | G3: M6 | H3: M7 | I3: M8 | J3: M9 | K3: M10 | L3: M11 | M3: M12 | N3: M13 | O3: M14 | P3: M15 | Q3: M16 | R3: M17 | S3: M18 | T3: M19 | U3: M20 | V3: M21 | W3: M22 | X3: M23 | Y3: M24
A4: Opening cash | B4: =ASSUMPTIONS!$C$39 -> 10000 | C4: =B15 -> 32633.066 | D4: =C15 -> 59409.69 | E4: =D15 -> 86240.476 | F4: =E15 -> 113126.33 | G4: =F15 -> 140068.17 | H4: =G15 -> 167066.93 | I4: =H15 -> 194123.58 | J4: =I15 -> 221239.06 | ... Y4: =X15 -> 634852.33
A5: Cash collected current month | B5: =FUNNEL_24M!B26*ASSUMPTIONS!$C$10 -> 37237.338 | C5: =FUNNEL_24M!C26*ASSUMPTIONS!$C$10 -> 37291.175 | D5: =FUNNEL_24M!D26*ASSUMPTIONS!$C$10 -> 37345.909 | E5: =FUNNEL_24M!E26*ASSUMPTIONS!$C$10 -> 37401.557 | F5: =FUNNEL_24M!F26*ASSUMPTIONS!$C$10 -> 37458.135 | G5: =FUNNEL_24M!G26*ASSUMPTIONS!$C$10 -> 37515.659 | H5: =FUNNEL_24M!H26*ASSUMPTIONS!$C$10 -> 37574.147 | I5: =FUNNEL_24M!I26*ASSUMPTIONS!$C$10 -> 37633.617 | ... Y5: =FUNNEL_24M!Y26*ASSUMPTIONS!$C$10 -> 38734.121
A6: Cash collected prior-month tail | B6: =0 -> 0 | C6: =FUNNEL_24M!B26*ASSUMPTIONS!$C$11 -> 4137.482 | D6: =FUNNEL_24M!C26*ASSUMPTIONS!$C$11 -> 4143.4639 | E6: =FUNNEL_24M!D26*ASSUMPTIONS!$C$11 -> 4149.5455 | F6: =FUNNEL_24M!E26*ASSUMPTIONS!$C$11 -> 4155.7286 | G6: =FUNNEL_24M!F26*ASSUMPTIONS!$C$11 -> 4162.015 | H6: =FUNNEL_24M!G26*ASSUMPTIONS!$C$11 -> 4168.4066 | I6: =FUNNEL_24M!H26*ASSUMPTIONS!$C$11 -> 4174.9053 | J6: =FUNNEL_24M!I26*ASSUMPTIONS!$C$11 -> 4181.513 | ... Y6: =FUNNEL_24M!X26*ASSUMPTIONS!$C$11 -> 4295.1441
A7: Total cash receipts after bad debt | B7: =(B5+B6)*(1-ASSUMPTIONS!$C$12) -> 36864.964 | C7: =(C5+C6)*(1-ASSUMPTIONS!$C$12) -> 41014.37 | D7: =(D5+D6)*(1-ASSUMPTIONS!$C$12) -> 41074.479 | E7: =(E5+E6)*(1-ASSUMPTIONS!$C$12) -> 41135.591 | F7: =(F5+F6)*(1-ASSUMPTIONS!$C$12) -> 41197.725 | G7: =(G5+G6)*(1-ASSUMPTIONS!$C$12) -> 41260.897 | H7: =(H5+H6)*(1-ASSUMPTIONS!$C$12) -> 41325.128 | I7: =(I5+I6)*(1-ASSUMPTIONS!$C$12) -> 41390.437 | ... Y7: =(Y5+Y6)*(1-ASSUMPTIONS!$C$12) -> 42598.973
A9: Direct variable cash out | B9: =PNL_24M!B17 -> 5511.8981 | C9: =PNL_24M!C17 -> 5517.7467 | D9: =PNL_24M!D17 -> 5523.6927 | E9: =PNL_24M!E17 -> 5529.738 | F9: =PNL_24M!F17 -> 5535.8842 | G9: =PNL_24M!G17 -> 5542.1333 | H9: =PNL_24M!H17 -> 5548.4872 | I9: =PNL_24M!I17 -> 5554.9476 | ... Y9: =PNL_24M!Y17 -> 5674.5
A10: Acquisition cash out | B10: =PNL_24M!B24 -> 6000 | C10: =PNL_24M!C24 -> 6000 | D10: =PNL_24M!D24 -> 6000 | E10: =PNL_24M!E24 -> 6000 | F10: =PNL_24M!F24 -> 6000 | G10: =PNL_24M!G24 -> 6000 | H10: =PNL_24M!H24 -> 6000 | I10: =PNL_24M!I24 -> 6000 | ... Y10: =PNL_24M!Y24 -> 6000
A11: Fixed OPEX cash out | B11: =PNL_24M!B36 -> 2720 | C11: =PNL_24M!C36 -> 2720 | D11: =PNL_24M!D36 -> 2720 | E11: =PNL_24M!E36 -> 2720 | F11: =PNL_24M!F36 -> 2720 | G11: =PNL_24M!G36 -> 2720 | H11: =PNL_24M!H36 -> 2720 | I11: =PNL_24M!I36 -> 2720 | ... Y11: =PNL_24M!Y36 -> 2801.6
A12: Total operating cash out | B12: =SUM(B9:B11) -> 14231.898 | C12: =SUM(C9:C11) -> 14237.747 | D12: =SUM(D9:D11) -> 14243.693 | E12: =SUM(E9:E11) -> 14249.738 | F12: =SUM(F9:F11) -> 14255.884 | G12: =SUM(G9:G11) -> 14262.133 | H12: =SUM(H9:H11) -> 14268.487 | I12: =SUM(I9:I11) -> 14274.948 | ... Y12: =SUM(Y9:Y11) -> 14476.1
A14: Net operating cash flow | B14: =B7-B12 -> 22633.066 | C14: =C7-C12 -> 26776.624 | D14: =D7-D12 -> 26830.787 | E14: =E7-E12 -> 26885.854 | F14: =F7-F12 -> 26941.84 | G14: =G7-G12 -> 26998.764 | H14: =H7-H12 -> 27056.641 | I14: =I7-I12 -> 27115.489 | ... Y14: =Y7-Y12 -> 28122.873
A15: Closing cash | B15: =B4+B14 -> 32633.066 | C15: =C4+C14 -> 59409.69 | D15: =D4+D14 -> 86240.476 | E15: =E4+E14 -> 113126.33 | F15: =F4+F14 -> 140068.17 | G15: =G4+G14 -> 167066.93 | H15: =H4+H14 -> 194123.58 | I15: =I4+I14 -> 221239.06 | ... Y15: =Y4+Y14 -> 662975.21
A18: Min cash balance | B18: =MIN(B15:Y15) -> 32633.066
A19: Months cash negative | B19: =COUNTIF(B15:Y15,"<0") -> 0
A20: Final cash | B20: =Y15 -> 662975.21

Sheet SENSITIVITY
A1: Sensibilidad - EBITDA mes 1
A3: Tabla 1 | B3: EBITDA del mes 1 según CPL (columnas) y close rate call (filas).
A5: Close rate | B5: 10 | C5: 12 | D5: 14 | E5: 16 | F5: 18 | G5: 20 | H5: 24 | I5: 28
